2024-12-30 15:16:38,465 INFO    MainThread:869211 [wandb_setup.py:_flush():68] Current SDK version is 0.19.1
2024-12-30 15:16:38,465 INFO    MainThread:869211 [wandb_setup.py:_flush():68] Configure stats pid to 869211
2024-12-30 15:16:38,465 INFO    MainThread:869211 [wandb_setup.py:_flush():68] Loading settings from /home/datpd1/.config/wandb/settings
2024-12-30 15:16:38,465 INFO    MainThread:869211 [wandb_setup.py:_flush():68] Loading settings from /home/datpd1/datpd/capstone/Fed_2024/system/wandb/settings
2024-12-30 15:16:38,465 INFO    MainThread:869211 [wandb_setup.py:_flush():68] Loading settings from environment variables
2024-12-30 15:16:38,465 INFO    MainThread:869211 [wandb_init.py:_log_setup():528] Logging user logs to /home/datpd1/datpd/capstone/Fed_2024/system/wandb/run-20241230_151638-c1di8v71/logs/debug.log
2024-12-30 15:16:38,465 INFO    MainThread:869211 [wandb_init.py:_log_setup():529] Logging internal logs to /home/datpd1/datpd/capstone/Fed_2024/system/wandb/run-20241230_151638-c1di8v71/logs/debug-internal.log
2024-12-30 15:16:38,465 INFO    MainThread:869211 [wandb_init.py:init():644] calling init triggers
2024-12-30 15:16:38,465 INFO    MainThread:869211 [wandb_init.py:init():650] wandb.init called with sweep_config: {}
config: {}
2024-12-30 15:16:38,465 INFO    MainThread:869211 [wandb_init.py:init():680] starting backend
2024-12-30 15:16:38,465 INFO    MainThread:869211 [wandb_init.py:init():684] sending inform_init request
2024-12-30 15:16:38,469 INFO    MainThread:869211 [backend.py:_multiprocessing_setup():104] multiprocessing start_methods=fork,spawn,forkserver, using: spawn
2024-12-30 15:16:38,469 INFO    MainThread:869211 [wandb_init.py:init():697] backend started and connected
2024-12-30 15:16:38,472 INFO    MainThread:869211 [wandb_init.py:init():790] updated telemetry
2024-12-30 15:16:38,490 INFO    MainThread:869211 [wandb_init.py:init():822] communicating run to backend with 90.0 second timeout
2024-12-30 15:16:38,987 ERROR   MainThread:869211 [wandb_init.py:init():849] encountered error: failed to upsert bucket: returned error 403 Forbidden: {"errors":[{"message":"permission denied","path":["upsertBucket"],"extensions":{"code":"PERMISSION_ERROR"}}],"data":{"upsertBucket":null}}
2024-12-30 15:16:38,988 ERROR   MainThread:869211 [wandb_init.py:init():1308] error in wandb.init()
Traceback (most recent call last):
  File "/home/datpd1/miniconda3/envs/datpd1/lib/python3.12/site-packages/wandb/sdk/wandb_init.py", line 1298, in init
    return wi.init()
           ^^^^^^^^^
  File "/home/datpd1/miniconda3/envs/datpd1/lib/python3.12/site-packages/wandb/sdk/wandb_init.py", line 855, in init
    raise error
wandb.errors.errors.CommError: failed to upsert bucket: returned error 403 Forbidden: {"errors":[{"message":"permission denied","path":["upsertBucket"],"extensions":{"code":"PERMISSION_ERROR"}}],"data":{"upsertBucket":null}}
2024-12-30 15:16:39,002 WARNING MsgRouterThr:869211 [router.py:message_loop():75] message_loop has been closed
